Starting to process 2 groups...
Processing group 1/2
Traceback (most recent call last):
  File "/home/kirill/miniconda3/lib/python3.13/asyncio/runners.py", line 118, in run
    return self._loop.run_until_complete(task)
           ~~~~~~~~~~~~~~~~~~~~~~~~~~~~~^^^^^^
  File "/home/kirill/miniconda3/lib/python3.13/asyncio/base_events.py", line 725, in run_until_complete
    return future.result()
           ~~~~~~~~~~~~~^^
  File "/home/kirill/miniconda3/lib/python3.13/site-packages/atroposlib/envs/base.py", line 959, in process_manager
    to_postprocess, _ = await self.collect_trajectories(item)
                        ^^^^^^^^^^^^^^^^^^^^^^^^^^^^^^^^^^^^^
  File "/home/kirill/hackathons/atropos-nrs15h/environments/hack0/llm_humor_server.py", line 61, in collect_trajectories
    chat_completions = await self.server.chat_completion(
                       ^^^^^^^^^^^^^^^^^^^^^^^^^^^^^^^^^^
    ...<3 lines>...
    )
    ^
  File "/home/kirill/miniconda3/lib/python3.13/site-packages/atroposlib/envs/server_handling/server_manager.py", line 176, in chat_completion
    return await self.servers[most_available_server].chat_completion(**kwargs)
           ^^^^^^^^^^^^^^^^^^^^^^^^^^^^^^^^^^^^^^^^^^^^^^^^^^^^^^^^^^^^^^^^^^^
  File "/home/kirill/miniconda3/lib/python3.13/site-packages/tenacity/asyncio/__init__.py", line 189, in async_wrapped
    return await copy(fn, *args, **kwargs)
           ^^^^^^^^^^^^^^^^^^^^^^^^^^^^^^^
  File "/home/kirill/miniconda3/lib/python3.13/site-packages/tenacity/asyncio/__init__.py", line 111, in __call__
    do = await self.iter(retry_state=retry_state)
         ^^^^^^^^^^^^^^^^^^^^^^^^^^^^^^^^^^^^^^^^
  File "/home/kirill/miniconda3/lib/python3.13/site-packages/tenacity/asyncio/__init__.py", line 153, in iter
    result = await action(retry_state)
             ^^^^^^^^^^^^^^^^^^^^^^^^^
  File "/home/kirill/miniconda3/lib/python3.13/site-packages/tenacity/_utils.py", line 99, in inner
    return call(*args, **kwargs)
  File "/home/kirill/miniconda3/lib/python3.13/site-packages/tenacity/__init__.py", line 400, in <lambda>
    self._add_action_func(lambda rs: rs.outcome.result())
                                     ~~~~~~~~~~~~~~~~~^^
  File "/home/kirill/miniconda3/lib/python3.13/concurrent/futures/_base.py", line 449, in result
    return self.__get_result()
           ~~~~~~~~~~~~~~~~~^^
  File "/home/kirill/miniconda3/lib/python3.13/concurrent/futures/_base.py", line 401, in __get_result
    raise self._exception
  File "/home/kirill/miniconda3/lib/python3.13/site-packages/tenacity/asyncio/__init__.py", line 114, in __call__
    result = await fn(*args, **kwargs)
             ^^^^^^^^^^^^^^^^^^^^^^^^^
  File "/home/kirill/miniconda3/lib/python3.13/site-packages/atroposlib/envs/server_handling/server_baseline.py", line 279, in chat_completion
    ret_data = await self._chat_comp(stat_dict, **kwargs)
               ^^^^^^^^^^^^^^^^^^^^^^^^^^^^^^^^^^^^^^^^^^
  File "/home/kirill/miniconda3/lib/python3.13/site-packages/tenacity/asyncio/__init__.py", line 189, in async_wrapped
    return await copy(fn, *args, **kwargs)
           ^^^^^^^^^^^^^^^^^^^^^^^^^^^^^^^
  File "/home/kirill/miniconda3/lib/python3.13/site-packages/tenacity/asyncio/__init__.py", line 111, in __call__
    do = await self.iter(retry_state=retry_state)
         ^^^^^^^^^^^^^^^^^^^^^^^^^^^^^^^^^^^^^^^^
  File "/home/kirill/miniconda3/lib/python3.13/site-packages/tenacity/asyncio/__init__.py", line 153, in iter
    result = await action(retry_state)
             ^^^^^^^^^^^^^^^^^^^^^^^^^
  File "/home/kirill/miniconda3/lib/python3.13/site-packages/tenacity/_utils.py", line 99, in inner
    return call(*args, **kwargs)
  File "/home/kirill/miniconda3/lib/python3.13/site-packages/tenacity/__init__.py", line 400, in <lambda>
    self._add_action_func(lambda rs: rs.outcome.result())
                                     ~~~~~~~~~~~~~~~~~^^
  File "/home/kirill/miniconda3/lib/python3.13/concurrent/futures/_base.py", line 449, in result
    return self.__get_result()
           ~~~~~~~~~~~~~~~~~^^
  File "/home/kirill/miniconda3/lib/python3.13/concurrent/futures/_base.py", line 401, in __get_result
    raise self._exception
  File "/home/kirill/miniconda3/lib/python3.13/site-packages/tenacity/asyncio/__init__.py", line 114, in __call__
    result = await fn(*args, **kwargs)
             ^^^^^^^^^^^^^^^^^^^^^^^^^
  File "/home/kirill/miniconda3/lib/python3.13/site-packages/atroposlib/envs/server_handling/server_baseline.py", line 233, in _chat_comp
    completions = await self._chat_completion_wrapper(**kwargs)
                  ^^^^^^^^^^^^^^^^^^^^^^^^^^^^^^^^^^^^^^^^^^^^^
  File "/home/kirill/miniconda3/lib/python3.13/site-packages/atroposlib/envs/server_handling/openai_server.py", line 78, in _chat_completion_wrapper
    completions = await self.openai.chat.completions.create(**kwargs)
                  ^^^^^^^^^^^^^^^^^^^^^^^^^^^^^^^^^^^^^^^^^^^^^^^^^^^
  File "/home/kirill/miniconda3/lib/python3.13/site-packages/openai/resources/chat/completions/completions.py", line 2028, in create
    return await self._post(
           ^^^^^^^^^^^^^^^^^
    ...<45 lines>...
    )
    ^
  File "/home/kirill/miniconda3/lib/python3.13/site-packages/openai/_base_client.py", line 1742, in post
    return await self.request(cast_to, opts, stream=stream, stream_cls=stream_cls)
           ^^^^^^^^^^^^^^^^^^^^^^^^^^^^^^^^^^^^^^^^^^^^^^^^^^^^^^^^^^^^^^^^^^^^^^^
  File "/home/kirill/miniconda3/lib/python3.13/site-packages/openai/_base_client.py", line 1484, in request
    response = await self._client.send(
               ^^^^^^^^^^^^^^^^^^^^^^^^
    ...<3 lines>...
    )
    ^
  File "/home/kirill/miniconda3/lib/python3.13/site-packages/httpx/_client.py", line 1629, in send
    response = await self._send_handling_auth(
               ^^^^^^^^^^^^^^^^^^^^^^^^^^^^^^^
    ...<4 lines>...
    )
    ^
  File "/home/kirill/miniconda3/lib/python3.13/site-packages/httpx/_client.py", line 1657, in _send_handling_auth
    response = await self._send_handling_redirects(
               ^^^^^^^^^^^^^^^^^^^^^^^^^^^^^^^^^^^^
    ...<3 lines>...
    )
    ^
  File "/home/kirill/miniconda3/lib/python3.13/site-packages/httpx/_client.py", line 1694, in _send_handling_redirects
    response = await self._send_single_request(request)
               ^^^^^^^^^^^^^^^^^^^^^^^^^^^^^^^^^^^^^^^^
  File "/home/kirill/miniconda3/lib/python3.13/site-packages/httpx/_client.py", line 1730, in _send_single_request
    response = await transport.handle_async_request(request)
               ^^^^^^^^^^^^^^^^^^^^^^^^^^^^^^^^^^^^^^^^^^^^^
  File "/home/kirill/miniconda3/lib/python3.13/site-packages/httpx/_transports/default.py", line 394, in handle_async_request
    resp = await self._pool.handle_async_request(req)
           ^^^^^^^^^^^^^^^^^^^^^^^^^^^^^^^^^^^^^^^^^^
  File "/home/kirill/miniconda3/lib/python3.13/site-packages/httpcore/_async/connection_pool.py", line 256, in handle_async_request
    raise exc from None
  File "/home/kirill/miniconda3/lib/python3.13/site-packages/httpcore/_async/connection_pool.py", line 236, in handle_async_request
    response = await connection.handle_async_request(
               ^^^^^^^^^^^^^^^^^^^^^^^^^^^^^^^^^^^^^^
        pool_request.request
        ^^^^^^^^^^^^^^^^^^^^
    )
    ^
  File "/home/kirill/miniconda3/lib/python3.13/site-packages/httpcore/_async/connection.py", line 103, in handle_async_request
    return await self._connection.handle_async_request(request)
           ^^^^^^^^^^^^^^^^^^^^^^^^^^^^^^^^^^^^^^^^^^^^^^^^^^^^
  File "/home/kirill/miniconda3/lib/python3.13/site-packages/httpcore/_async/http11.py", line 136, in handle_async_request
    raise exc
  File "/home/kirill/miniconda3/lib/python3.13/site-packages/httpcore/_async/http11.py", line 106, in handle_async_request
    ) = await self._receive_response_headers(**kwargs)
        ^^^^^^^^^^^^^^^^^^^^^^^^^^^^^^^^^^^^^^^^^^^^^^
  File "/home/kirill/miniconda3/lib/python3.13/site-packages/httpcore/_async/http11.py", line 177, in _receive_response_headers
    event = await self._receive_event(timeout=timeout)
            ^^^^^^^^^^^^^^^^^^^^^^^^^^^^^^^^^^^^^^^^^^
  File "/home/kirill/miniconda3/lib/python3.13/site-packages/httpcore/_async/http11.py", line 217, in _receive_event
    data = await self._network_stream.read(
           ^^^^^^^^^^^^^^^^^^^^^^^^^^^^^^^^
        self.READ_NUM_BYTES, timeout=timeout
        ^^^^^^^^^^^^^^^^^^^^^^^^^^^^^^^^^^^^
    )
    ^
  File "/home/kirill/miniconda3/lib/python3.13/site-packages/httpcore/_backends/anyio.py", line 35, in read
    return await self._stream.receive(max_bytes=max_bytes)
           ^^^^^^^^^^^^^^^^^^^^^^^^^^^^^^^^^^^^^^^^^^^^^^^
  File "/home/kirill/miniconda3/lib/python3.13/site-packages/anyio/streams/tls.py", line 219, in receive
    data = await self._call_sslobject_method(self._ssl_object.read, max_bytes)
           ^^^^^^^^^^^^^^^^^^^^^^^^^^^^^^^^^^^^^^^^^^^^^^^^^^^^^^^^^^^^^^^^^^^
  File "/home/kirill/miniconda3/lib/python3.13/site-packages/anyio/streams/tls.py", line 162, in _call_sslobject_method
    data = await self.transport_stream.receive()
           ^^^^^^^^^^^^^^^^^^^^^^^^^^^^^^^^^^^^^
  File "/home/kirill/miniconda3/lib/python3.13/site-packages/anyio/_backends/_asyncio.py", line 1254, in receive
    await self._protocol.read_event.wait()
  File "/home/kirill/miniconda3/lib/python3.13/asyncio/locks.py", line 213, in wait
    await fut
asyncio.exceptions.CancelledError

During handling of the above exception, another exception occurred:

Traceback (most recent call last):
  File "/home/kirill/hackathons/atropos-nrs15h/environments/hack0/llm_humor_server.py", line 101, in <module>
    HumorEnv.cli()
    ~~~~~~~~~~~~^^
  File "/home/kirill/miniconda3/lib/python3.13/site-packages/atroposlib/envs/base.py", line 1013, in cli
    run_and_exit(
    ~~~~~~~~~~~~^
        subcommands,
        ^^^^^^^^^^^^
        description=f"CLI for {cls.__name__}",
        ^^^^^^^^^^^^^^^^^^^^^^^^^^^^^^^^^^^^^^
        exception_handler=custom_error_handler,
        ^^^^^^^^^^^^^^^^^^^^^^^^^^^^^^^^^^^^^^^
    )
    ^
  File "/home/kirill/miniconda3/lib/python3.13/site-packages/pydantic_cli/__init__.py", line 644, in run_and_exit
    sys.exit(f(_args))
             ~^^^^^^^
  File "/home/kirill/miniconda3/lib/python3.13/site-packages/pydantic_cli/__init__.py", line 523, in f
    return _runner(
        args,
    ...<4 lines>...
        epilogue_handler,
    )
  File "/home/kirill/miniconda3/lib/python3.13/site-packages/pydantic_cli/__init__.py", line 326, in _runner
    out = cmd.run()
  File "/home/kirill/miniconda3/lib/python3.13/site-packages/atroposlib/envs/base.py", line 1382, in run
    asyncio.run(env.process_manager())
    ~~~~~~~~~~~^^^^^^^^^^^^^^^^^^^^^^^
  File "/home/kirill/miniconda3/lib/python3.13/asyncio/runners.py", line 195, in run
    return runner.run(main)
           ~~~~~~~~~~^^^^^^
  File "/home/kirill/miniconda3/lib/python3.13/asyncio/runners.py", line 123, in run
    raise KeyboardInterrupt()
KeyboardInterrupt
